<mujoco model="Quadruped URDF">
  <compiler angle="radian" meshdir="Quadruped URDF/meshes/"/>
  <asset>
    <mesh name="Body_bin" file="Body_bin.STL"/>
    <mesh name="Front Right Thigh" file="Front Right Thigh.STL"/>
    <mesh name="Front Right Shin" file="Front Right Shin.STL"/>
    <mesh name="Front Left Thigh" file="Front Left Thigh.STL"/>
    <mesh name="Front Left Shin" file="Front Left Shin.STL"/>
    <mesh name="Rear Right Thigh" file="Rear Right Thigh.STL"/>
    <mesh name="Rear Right Shin" file="Rear Right Shin.STL"/>
    <mesh name="Rear Left Thigh" file="Rear Left Thigh.STL"/>
    <mesh name="Rear Left Shin" file="Rear Left Shin.STL"/>
  </asset>
  <asset>
    <texture name="grid" type="2d" builtin="checker" rgb1=".1 .2 .3"
     rgb2=".2 .3 .4" width="300" height="300" mark="none"/>
    <material name="grid" texture="grid" texrepeat="6 6"
     texuniform="true" reflectance=".2"/>
     <material name="wall" rgba='.5 .5 .5 1'/>
  </asset>
  <worldbody>
    <light name="light" pos="-.2 0 1"/>
    <geom name="ground" type="plane" size=".5 .5 10" material="grid" contype="2" conaffinity="2"/> 
    <body name="Body" pos="0 0 .5">
      <geom name="Body" type="mesh" contype="2" conaffinity="2" group="1" density="0" rgba="0.385266 0.596728 0.703907 1" mesh="Body_bin"/>
      <joint name="Body Free" type="free"/>
      <inertial pos="0.0004967 -0.0019144 -0.00656282" quat="0.499113 0.500689 -0.500109 0.500088" mass="2.72713097" diaginertia="0.03707987 0.037216486 0.00367331"/>
      <body name="Front Right Thigh" pos="-0.15605 -0.1796 0" quat="0.286214 0.646591 -0.286219 -0.646591">
        <inertial pos="2.43741e-05 -0.0142051 -0.00547111" quat="0.499113 0.500689 -0.500109 0.500088" mass="0.513489" diaginertia="0.00102412 0.000703444 0.000379087"/>
        <joint name="Front Right Hip" pos="0 0 0" axis="0 0 1"/>
        <geom name="Front Right Thigh" type="mesh" contype="1" conaffinity="1" group="1" density="0" rgba=".580992 .393846 .712274 1" mesh="Front Right Thigh"/>
        <body name="Front Right Shin" pos="0 -0.13625 0.014875">
          <inertial pos="0.124878 -0.00732498 0.000175056" quat="0.0207105 0.70682 -0.0207132 0.706787" mass="0.12961" diaginertia="5.097e-05 4.99084e-05 3.51177e-05"/>
          <joint name="Front Right Knee" pos="0 0 0" axis="0 0 1"/>
          <geom name="Front Right Shin" type="mesh" contype="1" conaffinity="1" group="1" density="0" rgba="0.741616 0.534085 0.405905 1" mesh="Front Right Shin"/>
        </body>
      </body>
      <body name="Front Left Thigh" pos="0.15605 -0.1796 0" quat="0.286214 0.646591 -0.286219 -0.646591">
        <inertial pos="-2.69567e-06 -0.0142673 0.00542296" quat="0.500442 0.499547 -0.499649 0.500361" mass="0.513479" diaginertia="0.00102412 0.000703378 0.000379152"/>
        <joint name="Front Left Hip" pos="0 0 0" axis="0 0 -1"/>
        <geom name = "Front Left Thigh" type="mesh" contype="1" conaffinity="1" group="1" density="0" rgba=".580992 .393846 .712274 1" mesh="Front Left Thigh"/>
        <body name="Front Left Shin" pos="0 -0.13625 -0.015125">
          <inertial pos="0.124878 -0.00732498 0.000177556" quat="0.0207105 0.70682 -0.0207132 0.706787" mass="0.12961" diaginertia="5.097e-05 4.99084e-05 3.51177e-05"/>
          <joint name="Front Left Knee" pos="0 0 0" axis="0 0 1"/>
          <geom name="Front Left Shin" type="mesh" contype="1" conaffinity="1" group="1" density="0" rgba="0.741616 0.534085 0.405905 1" mesh="Front Left Shin"/>
        </body>
      </body>
      <body name="Rear Right Thigh" pos="-0.15605 0.1796 0" quat="0.286214 0.646591 -0.286219 -0.646591">
        <inertial pos="2.43741e-05 -0.0142051 -0.00547111" quat="0.499113 0.500689 -0.500109 0.500088" mass="0.513489" diaginertia="0.00102412 0.000703444 0.000379087"/>
        <joint name="Rear Right Hip" pos="0 0 0" axis="0 0 -1"/>
        <geom name="Rear Right Thigh" type="mesh" contype="1" conaffinity="1" group="1" density="0" rgba=".580992 .393846 .712274 1" mesh="Rear Right Thigh"/>
        <body name="Rear Right Shin" pos="0 -0.13625 0.015125">
          <inertial pos="0.124878 -0.00732498 0.000177556" quat="0.0207105 0.70682 -0.0207132 0.706787" mass="0.12961" diaginertia="5.097e-05 4.99084e-05 3.51177e-05"/>
          <joint name="Rear Right Knee" pos="0 0 0" axis="0 0 1"/>
          <geom name="Rear Right Shin" type="mesh" contype="1" conaffinity="1" group="1" density="0" rgba="0.741616 0.534085 0.405905 1" mesh="Rear Right Shin"/>
        </body>
      </body>
      <body name="Rear Left Thigh" pos="0.15605 0.1796 0" quat="0.286215 0.646592 -0.286215 -0.646592">
        <inertial pos="-2.69567e-06 -0.0142673 0.00542296" quat="0.500442 0.499547 -0.499649 0.500361" mass="0.513479" diaginertia="0.00102412 0.000703378 0.000379152"/>
        <joint name="Rear Left Hip" pos="0 0 0" axis="0 0 1"/>
        <geom name="Rear Left Thigh" type="mesh" contype="1" conaffinity="1" group="1" density="0" rgba=".580992 .393846 .712274 1" mesh="Rear Left Thigh"/>
        <body name="Rear Left Shin" pos="0 -0.13625 -0.015125">
          <inertial pos="0.124878 -0.00732498 0.000175056" quat="0.0207105 0.70682 -0.0207132 0.706787" mass="0.12961" diaginertia="5.097e-05 4.99084e-05 3.51177e-05"/>
          <joint name="Rear Left Knee" pos="0 0 0" axis="0 0 1"/>
          <geom name="Rear Left Shin" type="mesh" contype="1" conaffinity="1" group="1" density="0" rgba="0.741616 0.534085 0.405905 1" mesh="Rear Left Shin"/>
        </body>
      </body>
    </body>
  </worldbody>
</mujoco>